[2025-04-12T10:18:38.014+0000] {local_task_job_runner.py:123} INFO - ::group::Pre task execution logs
[2025-04-12T10:18:38.029+0000] {taskinstance.py:2614} INFO - Dependencies all met for dep_context=non-requeueable deps ti=<TaskInstance: weather_forecast_ingestion_dag.clean scheduled__2025-04-11T19:00:00+00:00 [queued]>
[2025-04-12T10:18:38.035+0000] {taskinstance.py:2614} INFO - Dependencies all met for dep_context=requeueable deps ti=<TaskInstance: weather_forecast_ingestion_dag.clean scheduled__2025-04-11T19:00:00+00:00 [queued]>
[2025-04-12T10:18:38.035+0000] {taskinstance.py:2867} INFO - Starting attempt 1 of 2
[2025-04-12T10:18:38.044+0000] {taskinstance.py:2890} INFO - Executing <Task(_PythonDecoratedOperator): clean> on 2025-04-11 19:00:00+00:00
[2025-04-12T10:18:38.048+0000] {warnings.py:112} WARNING - /home/***/.local/lib/python3.12/site-packages/***/task/task_runner/standard_task_runner.py:70: DeprecationWarning: This process (pid=226) is multi-threaded, use of fork() may lead to deadlocks in the child.
  pid = os.fork()

[2025-04-12T10:18:38.049+0000] {standard_task_runner.py:72} INFO - Started process 228 to run task
[2025-04-12T10:18:38.049+0000] {standard_task_runner.py:104} INFO - Running: ['***', 'tasks', 'run', 'weather_forecast_ingestion_dag', 'clean', 'scheduled__2025-04-11T19:00:00+00:00', '--job-id', '774', '--raw', '--subdir', 'DAGS_FOLDER/weather_forecast_ingestion_dag.py', '--cfg-path', '/tmp/tmp0wng3d5v']
[2025-04-12T10:18:38.051+0000] {standard_task_runner.py:105} INFO - Job 774: Subtask clean
[2025-04-12T10:18:38.088+0000] {task_command.py:467} INFO - Running <TaskInstance: weather_forecast_ingestion_dag.clean scheduled__2025-04-11T19:00:00+00:00 [running]> on host e1fcb75fb946
[2025-04-12T10:18:38.149+0000] {taskinstance.py:3134} INFO - Exporting env vars: AIRFLOW_CTX_DAG_OWNER='beni' AIRFLOW_CTX_DAG_ID='weather_forecast_ingestion_dag' AIRFLOW_CTX_TASK_ID='clean' AIRFLOW_CTX_EXECUTION_DATE='2025-04-11T19:00:00+00:00' AIRFLOW_CTX_TRY_NUMBER='1' AIRFLOW_CTX_DAG_RUN_ID='scheduled__2025-04-11T19:00:00+00:00'
[2025-04-12T10:18:38.150+0000] {taskinstance.py:732} INFO - ::endgroup::
[2025-04-12T10:18:38.263+0000] {connectionpool.py:868} WARNING - Retrying (Retry(total=2, connect=None, read=None, redirect=None, status=None)) after connection broken by 'NameResolutionError("<urllib3.connection.HTTPSConnection object at 0xffff74141a90>: Failed to resolve 'oauth2.googleapis.com' ([Errno -2] Name or service not known)")': /token
[2025-04-12T10:18:38.267+0000] {connectionpool.py:868} WARNING - Retrying (Retry(total=1, connect=None, read=None, redirect=None, status=None)) after connection broken by 'NameResolutionError("<urllib3.connection.HTTPSConnection object at 0xffff7412e6f0>: Failed to resolve 'oauth2.googleapis.com' ([Errno -2] Name or service not known)")': /token
[2025-04-12T10:18:38.271+0000] {connectionpool.py:868} WARNING - Retrying (Retry(total=0, connect=None, read=None, redirect=None, status=None)) after connection broken by 'NameResolutionError("<urllib3.connection.HTTPSConnection object at 0xffff7412eb70>: Failed to resolve 'oauth2.googleapis.com' ([Errno -2] Name or service not known)")': /token
[2025-04-12T10:18:39.050+0000] {connectionpool.py:868} WARNING - Retrying (Retry(total=2, connect=None, read=None, redirect=None, status=None)) after connection broken by 'NameResolutionError("<urllib3.connection.HTTPSConnection object at 0xffff7412f3e0>: Failed to resolve 'oauth2.googleapis.com' ([Errno -2] Name or service not known)")': /token
[2025-04-12T10:18:39.055+0000] {connectionpool.py:868} WARNING - Retrying (Retry(total=1, connect=None, read=None, redirect=None, status=None)) after connection broken by 'NameResolutionError("<urllib3.connection.HTTPSConnection object at 0xffff7412f800>: Failed to resolve 'oauth2.googleapis.com' ([Errno -2] Name or service not known)")': /token
[2025-04-12T10:18:39.059+0000] {connectionpool.py:868} WARNING - Retrying (Retry(total=0, connect=None, read=None, redirect=None, status=None)) after connection broken by 'NameResolutionError("<urllib3.connection.HTTPSConnection object at 0xffff7412fc80>: Failed to resolve 'oauth2.googleapis.com' ([Errno -2] Name or service not known)")': /token
[2025-04-12T10:18:39.532+0000] {connectionpool.py:868} WARNING - Retrying (Retry(total=2, connect=None, read=None, redirect=None, status=None)) after connection broken by 'NameResolutionError("<urllib3.connection.HTTPSConnection object at 0xffff73f58440>: Failed to resolve 'oauth2.googleapis.com' ([Errno -2] Name or service not known)")': /token
[2025-04-12T10:18:39.535+0000] {connectionpool.py:868} WARNING - Retrying (Retry(total=1, connect=None, read=None, redirect=None, status=None)) after connection broken by 'NameResolutionError("<urllib3.connection.HTTPSConnection object at 0xffff73f58800>: Failed to resolve 'oauth2.googleapis.com' ([Errno -2] Name or service not known)")': /token
[2025-04-12T10:18:39.537+0000] {connectionpool.py:868} WARNING - Retrying (Retry(total=0, connect=None, read=None, redirect=None, status=None)) after connection broken by 'NameResolutionError("<urllib3.connection.HTTPSConnection object at 0xffff73f589b0>: Failed to resolve 'oauth2.googleapis.com' ([Errno -2] Name or service not known)")': /token
[2025-04-12T10:18:42.497+0000] {connectionpool.py:868} WARNING - Retrying (Retry(total=2, connect=None, read=None, redirect=None, status=None)) after connection broken by 'NameResolutionError("<urllib3.connection.HTTPSConnection object at 0xffff73f590d0>: Failed to resolve 'oauth2.googleapis.com' ([Errno -2] Name or service not known)")': /token
[2025-04-12T10:18:42.502+0000] {connectionpool.py:868} WARNING - Retrying (Retry(total=1, connect=None, read=None, redirect=None, status=None)) after connection broken by 'NameResolutionError("<urllib3.connection.HTTPSConnection object at 0xffff73f59520>: Failed to resolve 'oauth2.googleapis.com' ([Errno -2] Name or service not known)")': /token
[2025-04-12T10:18:42.507+0000] {connectionpool.py:868} WARNING - Retrying (Retry(total=0, connect=None, read=None, redirect=None, status=None)) after connection broken by 'NameResolutionError("<urllib3.connection.HTTPSConnection object at 0xffff73f59970>: Failed to resolve 'oauth2.googleapis.com' ([Errno -2] Name or service not known)")': /token
[2025-04-12T10:18:50.750+0000] {logging_mixin.py:190} INFO - üóëÔ∏è Deleting outdated forecast: weather_forecast/bamberg/2025-04-11T1700.json
[2025-04-12T10:18:50.876+0000] {logging_mixin.py:190} INFO - üóëÔ∏è Deleting outdated forecast: weather_forecast/bamberg/2025-04-11T1800.json
[2025-04-12T10:18:50.995+0000] {logging_mixin.py:190} INFO - üóëÔ∏è Deleting outdated forecast: weather_forecast/bamberg/2025-04-11T1900.json
[2025-04-12T10:18:51.080+0000] {logging_mixin.py:190} INFO - üóëÔ∏è Deleting outdated forecast: weather_forecast/bamberg/2025-04-11T2000.json
[2025-04-12T10:18:51.217+0000] {logging_mixin.py:190} INFO - üóëÔ∏è Deleting outdated forecast: weather_forecast/bamberg/2025-04-12T0600.json
[2025-04-12T10:18:51.400+0000] {logging_mixin.py:190} INFO - üóëÔ∏è Deleting outdated forecast: weather_forecast/bamberg/2025-04-12T0700.json
[2025-04-12T10:18:51.500+0000] {logging_mixin.py:190} INFO - üóëÔ∏è Deleting outdated forecast: weather_forecast/bamberg/2025-04-12T0800.json
[2025-04-12T10:18:51.581+0000] {logging_mixin.py:190} INFO - üóëÔ∏è Deleting outdated forecast: weather_forecast/bamberg/2025-04-12T0900.json
[2025-04-12T10:18:51.755+0000] {logging_mixin.py:190} INFO - üóëÔ∏è Deleting outdated forecast: weather_forecast/bamberg/2025-04-12T1000.json
[2025-04-12T10:18:51.836+0000] {python.py:240} INFO - Done. Returned value was: None
[2025-04-12T10:18:51.858+0000] {taskinstance.py:341} INFO - ::group::Post task execution logs
[2025-04-12T10:18:51.859+0000] {taskinstance.py:353} INFO - Marking task as SUCCESS. dag_id=weather_forecast_ingestion_dag, task_id=clean, run_id=scheduled__2025-04-11T19:00:00+00:00, execution_date=20250411T190000, start_date=20250412T101838, end_date=20250412T101851
[2025-04-12T10:18:51.931+0000] {local_task_job_runner.py:266} INFO - Task exited with return code 0
[2025-04-12T10:18:51.945+0000] {taskinstance.py:3901} INFO - 0 downstream tasks scheduled from follow-on schedule check
[2025-04-12T10:18:51.947+0000] {local_task_job_runner.py:245} INFO - ::endgroup::
