[2025-04-12T11:38:37.132+0000] {local_task_job_runner.py:123} INFO - ::group::Pre task execution logs
[2025-04-12T11:38:37.143+0000] {taskinstance.py:2614} INFO - Dependencies all met for dep_context=non-requeueable deps ti=<TaskInstance: pollen_ingestion_dag.transform_pollen manual__2025-04-12T11:38:34.243242+00:00 [queued]>
[2025-04-12T11:38:37.147+0000] {taskinstance.py:2614} INFO - Dependencies all met for dep_context=requeueable deps ti=<TaskInstance: pollen_ingestion_dag.transform_pollen manual__2025-04-12T11:38:34.243242+00:00 [queued]>
[2025-04-12T11:38:37.148+0000] {taskinstance.py:2867} INFO - Starting attempt 1 of 2
[2025-04-12T11:38:37.153+0000] {taskinstance.py:2890} INFO - Executing <Task(BashOperator): transform_pollen> on 2025-04-12 11:38:34.243242+00:00
[2025-04-12T11:38:37.155+0000] {warnings.py:112} WARNING - /home/***/.local/lib/python3.12/site-packages/***/task/task_runner/standard_task_runner.py:70: DeprecationWarning: This process (pid=256) is multi-threaded, use of fork() may lead to deadlocks in the child.
  pid = os.fork()

[2025-04-12T11:38:37.156+0000] {standard_task_runner.py:72} INFO - Started process 257 to run task
[2025-04-12T11:38:37.157+0000] {standard_task_runner.py:104} INFO - Running: ['***', 'tasks', 'run', 'pollen_ingestion_dag', 'transform_pollen', 'manual__2025-04-12T11:38:34.243242+00:00', '--job-id', '783', '--raw', '--subdir', 'DAGS_FOLDER/pollen_ingestion_dag.py', '--cfg-path', '/tmp/tmpvcg9qllc']
[2025-04-12T11:38:37.158+0000] {standard_task_runner.py:105} INFO - Job 783: Subtask transform_pollen
[2025-04-12T11:38:37.184+0000] {task_command.py:467} INFO - Running <TaskInstance: pollen_ingestion_dag.transform_pollen manual__2025-04-12T11:38:34.243242+00:00 [running]> on host e1fcb75fb946
[2025-04-12T11:38:37.226+0000] {taskinstance.py:3134} INFO - Exporting env vars: AIRFLOW_CTX_DAG_OWNER='beni' AIRFLOW_CTX_DAG_ID='pollen_ingestion_dag' AIRFLOW_CTX_TASK_ID='transform_pollen' AIRFLOW_CTX_EXECUTION_DATE='2025-04-12T11:38:34.243242+00:00' AIRFLOW_CTX_TRY_NUMBER='1' AIRFLOW_CTX_DAG_RUN_ID='manual__2025-04-12T11:38:34.243242+00:00'
[2025-04-12T11:38:37.227+0000] {taskinstance.py:732} INFO - ::endgroup::
[2025-04-12T11:38:37.229+0000] {subprocess.py:78} INFO - Tmp dir root location: /tmp
[2025-04-12T11:38:37.230+0000] {subprocess.py:88} INFO - Running command: ['/usr/bin/bash', '-c', 'docker run --rm -v $(pwd)/fastapi/credentials:/app/credentials -e GOOGLE_APPLICATION_CREDENTIALS=/app/credentials/fastapi-gcs-key.json -v $(pwd)/spark:/app gooutside-spark spark-submit /app/transform_pollen.py']
[2025-04-12T11:38:37.234+0000] {subprocess.py:99} INFO - Output:
[2025-04-12T11:38:37.310+0000] {subprocess.py:106} INFO - docker: Cannot connect to the Docker daemon at unix:///var/run/docker.sock. Is the docker daemon running?.
[2025-04-12T11:38:37.311+0000] {subprocess.py:106} INFO - See 'docker run --help'.
[2025-04-12T11:38:37.311+0000] {subprocess.py:110} INFO - Command exited with return code 125
[2025-04-12T11:38:37.318+0000] {taskinstance.py:3313} ERROR - Task failed with exception
Traceback (most recent call last):
  File "/home/airflow/.local/lib/python3.12/site-packages/airflow/models/taskinstance.py", line 768, in _execute_task
    result = _execute_callable(context=context, **execute_callable_kwargs)
             ^^^^^^^^^^^^^^^^^^^^^^^^^^^^^^^^^^^^^^^^^^^^^^^^^^^^^^^^^^^^^
  File "/home/airflow/.local/lib/python3.12/site-packages/airflow/models/taskinstance.py", line 734, in _execute_callable
    return ExecutionCallableRunner(
           ^^^^^^^^^^^^^^^^^^^^^^^^
  File "/home/airflow/.local/lib/python3.12/site-packages/airflow/utils/operator_helpers.py", line 252, in run
    return self.func(*args, **kwargs)
           ^^^^^^^^^^^^^^^^^^^^^^^^^^
  File "/home/airflow/.local/lib/python3.12/site-packages/airflow/models/baseoperator.py", line 424, in wrapper
    return func(self, *args, **kwargs)
           ^^^^^^^^^^^^^^^^^^^^^^^^^^^
  File "/home/airflow/.local/lib/python3.12/site-packages/airflow/operators/bash.py", line 276, in execute
    raise AirflowException(
airflow.exceptions.AirflowException: Bash command failed. The command returned a non-zero exit code 125.
[2025-04-12T11:38:37.324+0000] {taskinstance.py:1226} INFO - Marking task as UP_FOR_RETRY. dag_id=pollen_ingestion_dag, task_id=transform_pollen, run_id=manual__2025-04-12T11:38:34.243242+00:00, execution_date=20250412T113834, start_date=20250412T113837, end_date=20250412T113837
[2025-04-12T11:38:37.341+0000] {taskinstance.py:341} INFO - ::group::Post task execution logs
[2025-04-12T11:38:37.342+0000] {standard_task_runner.py:124} ERROR - Failed to execute job 783 for task transform_pollen (Bash command failed. The command returned a non-zero exit code 125.; 257)
Traceback (most recent call last):
  File "/home/airflow/.local/lib/python3.12/site-packages/airflow/task/task_runner/standard_task_runner.py", line 117, in _start_by_fork
    ret = args.func(args, dag=self.dag)
          ^^^^^^^^^^^^^^^^^^^^^^^^^^^^^
  File "/home/airflow/.local/lib/python3.12/site-packages/airflow/cli/cli_config.py", line 49, in command
    return func(*args, **kwargs)
           ^^^^^^^^^^^^^^^^^^^^^
  File "/home/airflow/.local/lib/python3.12/site-packages/airflow/utils/cli.py", line 116, in wrapper
    return f(*args, **kwargs)
           ^^^^^^^^^^^^^^^^^^
  File "/home/airflow/.local/lib/python3.12/site-packages/airflow/cli/commands/task_command.py", line 483, in task_run
    task_return_code = _run_task_by_selected_method(args, _dag, ti)
                       ^^^^^^^^^^^^^^^^^^^^^^^^^^^^^^^^^^^^^^^^^^^^
  File "/home/airflow/.local/lib/python3.12/site-packages/airflow/cli/commands/task_command.py", line 256, in _run_task_by_selected_method
    return _run_raw_task(args, ti)
           ^^^^^^^^^^^^^^^^^^^^^^^
  File "/home/airflow/.local/lib/python3.12/site-packages/airflow/cli/commands/task_command.py", line 341, in _run_raw_task
    return ti._run_raw_task(
           ^^^^^^^^^^^^^^^^^
  File "/home/airflow/.local/lib/python3.12/site-packages/airflow/utils/session.py", line 97, in wrapper
    return func(*args, session=session, **kwargs)
           ^^^^^^^^^^^^^^^^^^^^^^^^^^^^^^^^^^^^^^
  File "/home/airflow/.local/lib/python3.12/site-packages/airflow/models/taskinstance.py", line 3006, in _run_raw_task
    return _run_raw_task(
           ^^^^^^^^^^^^^^
  File "/home/airflow/.local/lib/python3.12/site-packages/airflow/models/taskinstance.py", line 274, in _run_raw_task
    TaskInstance._execute_task_with_callbacks(
  File "/home/airflow/.local/lib/python3.12/site-packages/airflow/models/taskinstance.py", line 3161, in _execute_task_with_callbacks
    result = self._execute_task(context, task_orig)
             ^^^^^^^^^^^^^^^^^^^^^^^^^^^^^^^^^^^^^^
  File "/home/airflow/.local/lib/python3.12/site-packages/airflow/models/taskinstance.py", line 3185, in _execute_task
    return _execute_task(self, context, task_orig)
           ^^^^^^^^^^^^^^^^^^^^^^^^^^^^^^^^^^^^^^^
  File "/home/airflow/.local/lib/python3.12/site-packages/airflow/models/taskinstance.py", line 768, in _execute_task
    result = _execute_callable(context=context, **execute_callable_kwargs)
             ^^^^^^^^^^^^^^^^^^^^^^^^^^^^^^^^^^^^^^^^^^^^^^^^^^^^^^^^^^^^^
  File "/home/airflow/.local/lib/python3.12/site-packages/airflow/models/taskinstance.py", line 734, in _execute_callable
    return ExecutionCallableRunner(
           ^^^^^^^^^^^^^^^^^^^^^^^^
  File "/home/airflow/.local/lib/python3.12/site-packages/airflow/utils/operator_helpers.py", line 252, in run
    return self.func(*args, **kwargs)
           ^^^^^^^^^^^^^^^^^^^^^^^^^^
  File "/home/airflow/.local/lib/python3.12/site-packages/airflow/models/baseoperator.py", line 424, in wrapper
    return func(self, *args, **kwargs)
           ^^^^^^^^^^^^^^^^^^^^^^^^^^^
  File "/home/airflow/.local/lib/python3.12/site-packages/airflow/operators/bash.py", line 276, in execute
    raise AirflowException(
airflow.exceptions.AirflowException: Bash command failed. The command returned a non-zero exit code 125.
[2025-04-12T11:38:37.387+0000] {local_task_job_runner.py:266} INFO - Task exited with return code 1
[2025-04-12T11:38:37.404+0000] {taskinstance.py:3901} INFO - 0 downstream tasks scheduled from follow-on schedule check
[2025-04-12T11:38:37.405+0000] {local_task_job_runner.py:245} INFO - ::endgroup::
