[2025-04-12T10:18:36.414+0000] {local_task_job_runner.py:123} INFO - ::group::Pre task execution logs
[2025-04-12T10:18:36.455+0000] {taskinstance.py:2614} INFO - Dependencies all met for dep_context=non-requeueable deps ti=<TaskInstance: update_weather_dag.update_yesterday scheduled__2025-04-11T03:00:00+00:00 [queued]>
[2025-04-12T10:18:36.465+0000] {taskinstance.py:2614} INFO - Dependencies all met for dep_context=requeueable deps ti=<TaskInstance: update_weather_dag.update_yesterday scheduled__2025-04-11T03:00:00+00:00 [queued]>
[2025-04-12T10:18:36.466+0000] {taskinstance.py:2867} INFO - Starting attempt 1 of 2
[2025-04-12T10:18:36.481+0000] {taskinstance.py:2890} INFO - Executing <Task(_PythonDecoratedOperator): update_yesterday> on 2025-04-11 03:00:00+00:00
[2025-04-12T10:18:36.492+0000] {warnings.py:112} WARNING - /home/***/.local/lib/python3.12/site-packages/***/task/task_runner/standard_task_runner.py:70: DeprecationWarning: This process (pid=202) is multi-threaded, use of fork() may lead to deadlocks in the child.
  pid = os.fork()

[2025-04-12T10:18:36.497+0000] {standard_task_runner.py:72} INFO - Started process 210 to run task
[2025-04-12T10:18:36.496+0000] {standard_task_runner.py:104} INFO - Running: ['***', 'tasks', 'run', 'update_weather_dag', 'update_yesterday', 'scheduled__2025-04-11T03:00:00+00:00', '--job-id', '767', '--raw', '--subdir', 'DAGS_FOLDER/update_weather_dag.py', '--cfg-path', '/tmp/tmp4x7e8flh']
[2025-04-12T10:18:36.505+0000] {standard_task_runner.py:105} INFO - Job 767: Subtask update_yesterday
[2025-04-12T10:18:36.645+0000] {task_command.py:467} INFO - Running <TaskInstance: update_weather_dag.update_yesterday scheduled__2025-04-11T03:00:00+00:00 [running]> on host e1fcb75fb946
[2025-04-12T10:18:36.842+0000] {taskinstance.py:3134} INFO - Exporting env vars: AIRFLOW_CTX_DAG_OWNER='beni' AIRFLOW_CTX_DAG_ID='update_weather_dag' AIRFLOW_CTX_TASK_ID='update_yesterday' AIRFLOW_CTX_EXECUTION_DATE='2025-04-11T03:00:00+00:00' AIRFLOW_CTX_TRY_NUMBER='1' AIRFLOW_CTX_DAG_RUN_ID='scheduled__2025-04-11T03:00:00+00:00'
[2025-04-12T10:18:36.843+0000] {taskinstance.py:732} INFO - ::endgroup::
[2025-04-12T10:18:36.852+0000] {update_weather_dag.py:32} INFO - üîÅ Reloading historical weather data for 2025-04-11
[2025-04-12T10:18:36.889+0000] {logging_mixin.py:190} INFO - ‚ùå API Error: HTTPSConnectionPool(host='api.brightsky.dev', port=443): Max retries exceeded with url: /weather?lat=49.89&lon=10.89&date=2025-04-11&tz=Etc%2FUTC (Caused by NameResolutionError("<urllib3.connection.HTTPSConnection object at 0xffff74086f60>: Failed to resolve 'api.brightsky.dev' ([Errno -2] Name or service not known)"))
[2025-04-12T10:18:36.889+0000] {python.py:240} INFO - Done. Returned value was: None
[2025-04-12T10:18:36.917+0000] {taskinstance.py:341} INFO - ::group::Post task execution logs
[2025-04-12T10:18:36.918+0000] {taskinstance.py:353} INFO - Marking task as SUCCESS. dag_id=update_weather_dag, task_id=update_yesterday, run_id=scheduled__2025-04-11T03:00:00+00:00, execution_date=20250411T030000, start_date=20250412T101836, end_date=20250412T101836
[2025-04-12T10:18:37.013+0000] {local_task_job_runner.py:266} INFO - Task exited with return code 0
[2025-04-12T10:18:37.039+0000] {taskinstance.py:3901} INFO - 0 downstream tasks scheduled from follow-on schedule check
[2025-04-12T10:18:37.044+0000] {local_task_job_runner.py:245} INFO - ::endgroup::
