[2025-04-08T14:37:03.402+0000] {local_task_job_runner.py:123} INFO - ::group::Pre task execution logs
[2025-04-08T14:37:03.472+0000] {taskinstance.py:2614} INFO - Dependencies all met for dep_context=non-requeueable deps ti=<TaskInstance: air_ingestion_dag.ingest backfill__2024-01-03T06:00:00+00:00 [queued]>
[2025-04-08T14:37:03.490+0000] {taskinstance.py:2614} INFO - Dependencies all met for dep_context=requeueable deps ti=<TaskInstance: air_ingestion_dag.ingest backfill__2024-01-03T06:00:00+00:00 [queued]>
[2025-04-08T14:37:03.493+0000] {taskinstance.py:2867} INFO - Starting attempt 1 of 2
[2025-04-08T14:37:03.525+0000] {taskinstance.py:2890} INFO - Executing <Task(_PythonDecoratedOperator): ingest> on 2024-01-03 06:00:00+00:00
[2025-04-08T14:37:03.547+0000] {warnings.py:112} WARNING - /home/***/.local/lib/python3.12/site-packages/***/task/task_runner/standard_task_runner.py:70: DeprecationWarning: This process (pid=219) is multi-threaded, use of fork() may lead to deadlocks in the child.
  pid = os.fork()

[2025-04-08T14:37:03.550+0000] {standard_task_runner.py:72} INFO - Started process 238 to run task
[2025-04-08T14:37:03.546+0000] {standard_task_runner.py:104} INFO - Running: ['***', 'tasks', 'run', 'air_ingestion_dag', 'ingest', 'backfill__2024-01-03T06:00:00+00:00', '--job-id', '349', '--pool', 'default_pool', '--raw', '--subdir', 'DAGS_FOLDER/air_ingestion_dag.py', '--cfg-path', '/tmp/tmprjpqb2cg']
[2025-04-08T14:37:03.570+0000] {standard_task_runner.py:105} INFO - Job 349: Subtask ingest
[2025-04-08T14:37:03.824+0000] {task_command.py:467} INFO - Running <TaskInstance: air_ingestion_dag.ingest backfill__2024-01-03T06:00:00+00:00 [running]> on host ef6176db86b3
[2025-04-08T14:37:04.175+0000] {taskinstance.py:3134} INFO - Exporting env vars: AIRFLOW_CTX_DAG_OWNER='beni' AIRFLOW_CTX_DAG_ID='air_ingestion_dag' AIRFLOW_CTX_TASK_ID='ingest' AIRFLOW_CTX_EXECUTION_DATE='2024-01-03T06:00:00+00:00' AIRFLOW_CTX_TRY_NUMBER='1' AIRFLOW_CTX_DAG_RUN_ID='backfill__2024-01-03T06:00:00+00:00'
[2025-04-08T14:37:04.181+0000] {taskinstance.py:732} INFO - ::endgroup::
[2025-04-08T14:37:04.186+0000] {logging_mixin.py:190} INFO - ⏰ Running for local time: 2024-01-03T07:00:00+01:00 (UTC: 2024-01-03T06:00:00+00:00)
[2025-04-08T14:37:05.422+0000] {logging_mixin.py:190} INFO - ✅ Saved: gs://gooutside-raw/air/bamberg/2024-01-03T0600.json
[2025-04-08T14:37:05.824+0000] {logging_mixin.py:190} INFO - ✅ Saved: gs://gooutside-raw/air/bamberg/2024-01-03T0700.json
[2025-04-08T14:37:06.201+0000] {logging_mixin.py:190} INFO - ✅ Saved: gs://gooutside-raw/air/bamberg/2024-01-03T0800.json
[2025-04-08T14:37:06.535+0000] {logging_mixin.py:190} INFO - ✅ Saved: gs://gooutside-raw/air/bamberg/2024-01-03T0900.json
[2025-04-08T14:37:06.864+0000] {logging_mixin.py:190} INFO - ✅ Saved: gs://gooutside-raw/air/bamberg/2024-01-03T1000.json
[2025-04-08T14:37:07.173+0000] {logging_mixin.py:190} INFO - ✅ Saved: gs://gooutside-raw/air/bamberg/2024-01-03T1100.json
[2025-04-08T14:37:07.496+0000] {logging_mixin.py:190} INFO - ✅ Saved: gs://gooutside-raw/air/bamberg/2024-01-03T1200.json
[2025-04-08T14:37:07.826+0000] {logging_mixin.py:190} INFO - ✅ Saved: gs://gooutside-raw/air/bamberg/2024-01-03T1300.json
[2025-04-08T14:37:08.162+0000] {logging_mixin.py:190} INFO - ✅ Saved: gs://gooutside-raw/air/bamberg/2024-01-03T1400.json
[2025-04-08T14:37:08.493+0000] {taskinstance.py:3313} ERROR - Task failed with exception
Traceback (most recent call last):
  File "/home/airflow/.local/lib/python3.12/site-packages/google/cloud/storage/blob.py", line 2700, in _prep_and_do_upload
    created_json = self._do_upload(
                   ^^^^^^^^^^^^^^^^
  File "/home/airflow/.local/lib/python3.12/site-packages/google/cloud/storage/blob.py", line 2506, in _do_upload
    response = self._do_multipart_upload(
               ^^^^^^^^^^^^^^^^^^^^^^^^^^
  File "/home/airflow/.local/lib/python3.12/site-packages/google/cloud/storage/blob.py", line 2007, in _do_multipart_upload
    response = upload.transmit(
               ^^^^^^^^^^^^^^^^
  File "/home/airflow/.local/lib/python3.12/site-packages/google/resumable_media/requests/upload.py", line 153, in transmit
    return _request_helpers.wait_and_retry(
           ^^^^^^^^^^^^^^^^^^^^^^^^^^^^^^^^
  File "/home/airflow/.local/lib/python3.12/site-packages/google/resumable_media/requests/_request_helpers.py", line 178, in wait_and_retry
    raise error
  File "/home/airflow/.local/lib/python3.12/site-packages/google/resumable_media/requests/_request_helpers.py", line 155, in wait_and_retry
    response = func()
               ^^^^^^
  File "/home/airflow/.local/lib/python3.12/site-packages/google/resumable_media/requests/upload.py", line 149, in retriable_request
    self._process_response(result)
  File "/home/airflow/.local/lib/python3.12/site-packages/google/resumable_media/_upload.py", line 125, in _process_response
    _helpers.require_status_code(response, (http.client.OK,), self._get_status_code)
  File "/home/airflow/.local/lib/python3.12/site-packages/google/resumable_media/_helpers.py", line 108, in require_status_code
    raise common.InvalidResponse(
google.resumable_media.common.InvalidResponse: ('Request failed with status code', 429, 'Expected one of', 200)

During handling of the above exception, another exception occurred:

Traceback (most recent call last):
  File "/home/airflow/.local/lib/python3.12/site-packages/airflow/models/taskinstance.py", line 768, in _execute_task
    result = _execute_callable(context=context, **execute_callable_kwargs)
             ^^^^^^^^^^^^^^^^^^^^^^^^^^^^^^^^^^^^^^^^^^^^^^^^^^^^^^^^^^^^^
  File "/home/airflow/.local/lib/python3.12/site-packages/airflow/models/taskinstance.py", line 734, in _execute_callable
    return ExecutionCallableRunner(
           ^^^^^^^^^^^^^^^^^^^^^^^^
  File "/home/airflow/.local/lib/python3.12/site-packages/airflow/utils/operator_helpers.py", line 252, in run
    return self.func(*args, **kwargs)
           ^^^^^^^^^^^^^^^^^^^^^^^^^^
  File "/home/airflow/.local/lib/python3.12/site-packages/airflow/models/baseoperator.py", line 424, in wrapper
    return func(self, *args, **kwargs)
           ^^^^^^^^^^^^^^^^^^^^^^^^^^^
  File "/home/airflow/.local/lib/python3.12/site-packages/airflow/decorators/base.py", line 266, in execute
    return_value = super().execute(context)
                   ^^^^^^^^^^^^^^^^^^^^^^^^
  File "/home/airflow/.local/lib/python3.12/site-packages/airflow/models/baseoperator.py", line 424, in wrapper
    return func(self, *args, **kwargs)
           ^^^^^^^^^^^^^^^^^^^^^^^^^^^
  File "/home/airflow/.local/lib/python3.12/site-packages/airflow/operators/python.py", line 238, in execute
    return_value = self.execute_callable()
                   ^^^^^^^^^^^^^^^^^^^^^^^
  File "/home/airflow/.local/lib/python3.12/site-packages/airflow/operators/python.py", line 256, in execute_callable
    return runner.run(*self.op_args, **self.op_kwargs)
           ^^^^^^^^^^^^^^^^^^^^^^^^^^^^^^^^^^^^^^^^^^^
  File "/home/airflow/.local/lib/python3.12/site-packages/airflow/utils/operator_helpers.py", line 252, in run
    return self.func(*args, **kwargs)
           ^^^^^^^^^^^^^^^^^^^^^^^^^^
  File "/opt/airflow/dags/air_ingestion_dag.py", line 45, in ingest
    save_air_entry_to_gcs(entry)
  File "/opt/airflow/app/ingestion/air.py", line 124, in save_air_entry_to_gcs
    blob.upload_from_string(
  File "/usr/local/lib/python3.12/contextlib.py", line 81, in inner
    return func(*args, **kwds)
           ^^^^^^^^^^^^^^^^^^^
  File "/home/airflow/.local/lib/python3.12/site-packages/google/cloud/storage/blob.py", line 3128, in upload_from_string
    self.upload_from_file(
  File "/usr/local/lib/python3.12/contextlib.py", line 81, in inner
    return func(*args, **kwds)
           ^^^^^^^^^^^^^^^^^^^
  File "/home/airflow/.local/lib/python3.12/site-packages/google/cloud/storage/blob.py", line 2851, in upload_from_file
    self._prep_and_do_upload(
  File "/home/airflow/.local/lib/python3.12/site-packages/google/cloud/storage/blob.py", line 2718, in _prep_and_do_upload
    _raise_from_invalid_response(exc)
  File "/home/airflow/.local/lib/python3.12/site-packages/google/cloud/storage/blob.py", line 4908, in _raise_from_invalid_response
    raise exceptions.from_http_status(response.status_code, message, response=response)
google.api_core.exceptions.TooManyRequests: 429 POST https://storage.googleapis.com/upload/storage/v1/b/gooutside-raw/o?uploadType=multipart: {
  "error": {
    "code": 429,
    "message": "The object gooutside-raw/air/bamberg/2024-01-03T1500.json exceeded the rate limit for object mutation operations (create, update, and delete). Please reduce your request rate. See https://cloud.google.com/storage/docs/gcs429.",
    "errors": [
      {
        "message": "The object gooutside-raw/air/bamberg/2024-01-03T1500.json exceeded the rate limit for object mutation operations (create, update, and delete). Please reduce your request rate. See https://cloud.google.com/storage/docs/gcs429.",
        "domain": "usageLimits",
        "reason": "rateLimitExceeded"
      }
    ]
  }
}
: ('Request failed with status code', 429, 'Expected one of', <HTTPStatus.OK: 200>)
[2025-04-08T14:37:08.518+0000] {taskinstance.py:1226} INFO - Marking task as UP_FOR_RETRY. dag_id=air_ingestion_dag, task_id=ingest, run_id=backfill__2024-01-03T06:00:00+00:00, execution_date=20240103T060000, start_date=20250408T143703, end_date=20250408T143708
[2025-04-08T14:37:08.557+0000] {taskinstance.py:341} INFO - ::group::Post task execution logs
[2025-04-08T14:37:08.558+0000] {standard_task_runner.py:124} ERROR - Failed to execute job 349 for task ingest (429 POST https://storage.googleapis.com/upload/storage/v1/b/gooutside-raw/o?uploadType=multipart: {
  "error": {
    "code": 429,
    "message": "The object gooutside-raw/air/bamberg/2024-01-03T1500.json exceeded the rate limit for object mutation operations (create, update, and delete). Please reduce your request rate. See https://cloud.google.com/storage/docs/gcs429.",
    "errors": [
      {
        "message": "The object gooutside-raw/air/bamberg/2024-01-03T1500.json exceeded the rate limit for object mutation operations (create, update, and delete). Please reduce your request rate. See https://cloud.google.com/storage/docs/gcs429.",
        "domain": "usageLimits",
        "reason": "rateLimitExceeded"
      }
    ]
  }
}
: ('Request failed with status code', 429, 'Expected one of', <HTTPStatus.OK: 200>); 238)
Traceback (most recent call last):
  File "/home/airflow/.local/lib/python3.12/site-packages/google/cloud/storage/blob.py", line 2700, in _prep_and_do_upload
    created_json = self._do_upload(
                   ^^^^^^^^^^^^^^^^
  File "/home/airflow/.local/lib/python3.12/site-packages/google/cloud/storage/blob.py", line 2506, in _do_upload
    response = self._do_multipart_upload(
               ^^^^^^^^^^^^^^^^^^^^^^^^^^
  File "/home/airflow/.local/lib/python3.12/site-packages/google/cloud/storage/blob.py", line 2007, in _do_multipart_upload
    response = upload.transmit(
               ^^^^^^^^^^^^^^^^
  File "/home/airflow/.local/lib/python3.12/site-packages/google/resumable_media/requests/upload.py", line 153, in transmit
    return _request_helpers.wait_and_retry(
           ^^^^^^^^^^^^^^^^^^^^^^^^^^^^^^^^
  File "/home/airflow/.local/lib/python3.12/site-packages/google/resumable_media/requests/_request_helpers.py", line 178, in wait_and_retry
    raise error
  File "/home/airflow/.local/lib/python3.12/site-packages/google/resumable_media/requests/_request_helpers.py", line 155, in wait_and_retry
    response = func()
               ^^^^^^
  File "/home/airflow/.local/lib/python3.12/site-packages/google/resumable_media/requests/upload.py", line 149, in retriable_request
    self._process_response(result)
  File "/home/airflow/.local/lib/python3.12/site-packages/google/resumable_media/_upload.py", line 125, in _process_response
    _helpers.require_status_code(response, (http.client.OK,), self._get_status_code)
  File "/home/airflow/.local/lib/python3.12/site-packages/google/resumable_media/_helpers.py", line 108, in require_status_code
    raise common.InvalidResponse(
google.resumable_media.common.InvalidResponse: ('Request failed with status code', 429, 'Expected one of', 200)

During handling of the above exception, another exception occurred:

Traceback (most recent call last):
  File "/home/airflow/.local/lib/python3.12/site-packages/airflow/task/task_runner/standard_task_runner.py", line 117, in _start_by_fork
    ret = args.func(args, dag=self.dag)
          ^^^^^^^^^^^^^^^^^^^^^^^^^^^^^
  File "/home/airflow/.local/lib/python3.12/site-packages/airflow/cli/cli_config.py", line 49, in command
    return func(*args, **kwargs)
           ^^^^^^^^^^^^^^^^^^^^^
  File "/home/airflow/.local/lib/python3.12/site-packages/airflow/utils/cli.py", line 116, in wrapper
    return f(*args, **kwargs)
           ^^^^^^^^^^^^^^^^^^
  File "/home/airflow/.local/lib/python3.12/site-packages/airflow/cli/commands/task_command.py", line 483, in task_run
    task_return_code = _run_task_by_selected_method(args, _dag, ti)
                       ^^^^^^^^^^^^^^^^^^^^^^^^^^^^^^^^^^^^^^^^^^^^
  File "/home/airflow/.local/lib/python3.12/site-packages/airflow/cli/commands/task_command.py", line 256, in _run_task_by_selected_method
    return _run_raw_task(args, ti)
           ^^^^^^^^^^^^^^^^^^^^^^^
  File "/home/airflow/.local/lib/python3.12/site-packages/airflow/cli/commands/task_command.py", line 341, in _run_raw_task
    return ti._run_raw_task(
           ^^^^^^^^^^^^^^^^^
  File "/home/airflow/.local/lib/python3.12/site-packages/airflow/utils/session.py", line 97, in wrapper
    return func(*args, session=session, **kwargs)
           ^^^^^^^^^^^^^^^^^^^^^^^^^^^^^^^^^^^^^^
  File "/home/airflow/.local/lib/python3.12/site-packages/airflow/models/taskinstance.py", line 3006, in _run_raw_task
    return _run_raw_task(
           ^^^^^^^^^^^^^^
  File "/home/airflow/.local/lib/python3.12/site-packages/airflow/models/taskinstance.py", line 274, in _run_raw_task
    TaskInstance._execute_task_with_callbacks(
  File "/home/airflow/.local/lib/python3.12/site-packages/airflow/models/taskinstance.py", line 3161, in _execute_task_with_callbacks
    result = self._execute_task(context, task_orig)
             ^^^^^^^^^^^^^^^^^^^^^^^^^^^^^^^^^^^^^^
  File "/home/airflow/.local/lib/python3.12/site-packages/airflow/models/taskinstance.py", line 3185, in _execute_task
    return _execute_task(self, context, task_orig)
           ^^^^^^^^^^^^^^^^^^^^^^^^^^^^^^^^^^^^^^^
  File "/home/airflow/.local/lib/python3.12/site-packages/airflow/models/taskinstance.py", line 768, in _execute_task
    result = _execute_callable(context=context, **execute_callable_kwargs)
             ^^^^^^^^^^^^^^^^^^^^^^^^^^^^^^^^^^^^^^^^^^^^^^^^^^^^^^^^^^^^^
  File "/home/airflow/.local/lib/python3.12/site-packages/airflow/models/taskinstance.py", line 734, in _execute_callable
    return ExecutionCallableRunner(
           ^^^^^^^^^^^^^^^^^^^^^^^^
  File "/home/airflow/.local/lib/python3.12/site-packages/airflow/utils/operator_helpers.py", line 252, in run
    return self.func(*args, **kwargs)
           ^^^^^^^^^^^^^^^^^^^^^^^^^^
  File "/home/airflow/.local/lib/python3.12/site-packages/airflow/models/baseoperator.py", line 424, in wrapper
    return func(self, *args, **kwargs)
           ^^^^^^^^^^^^^^^^^^^^^^^^^^^
  File "/home/airflow/.local/lib/python3.12/site-packages/airflow/decorators/base.py", line 266, in execute
    return_value = super().execute(context)
                   ^^^^^^^^^^^^^^^^^^^^^^^^
  File "/home/airflow/.local/lib/python3.12/site-packages/airflow/models/baseoperator.py", line 424, in wrapper
    return func(self, *args, **kwargs)
           ^^^^^^^^^^^^^^^^^^^^^^^^^^^
  File "/home/airflow/.local/lib/python3.12/site-packages/airflow/operators/python.py", line 238, in execute
    return_value = self.execute_callable()
                   ^^^^^^^^^^^^^^^^^^^^^^^
  File "/home/airflow/.local/lib/python3.12/site-packages/airflow/operators/python.py", line 256, in execute_callable
    return runner.run(*self.op_args, **self.op_kwargs)
           ^^^^^^^^^^^^^^^^^^^^^^^^^^^^^^^^^^^^^^^^^^^
  File "/home/airflow/.local/lib/python3.12/site-packages/airflow/utils/operator_helpers.py", line 252, in run
    return self.func(*args, **kwargs)
           ^^^^^^^^^^^^^^^^^^^^^^^^^^
  File "/opt/airflow/dags/air_ingestion_dag.py", line 45, in ingest
    save_air_entry_to_gcs(entry)
  File "/opt/airflow/app/ingestion/air.py", line 124, in save_air_entry_to_gcs
    blob.upload_from_string(
  File "/usr/local/lib/python3.12/contextlib.py", line 81, in inner
    return func(*args, **kwds)
           ^^^^^^^^^^^^^^^^^^^
  File "/home/airflow/.local/lib/python3.12/site-packages/google/cloud/storage/blob.py", line 3128, in upload_from_string
    self.upload_from_file(
  File "/usr/local/lib/python3.12/contextlib.py", line 81, in inner
    return func(*args, **kwds)
           ^^^^^^^^^^^^^^^^^^^
  File "/home/airflow/.local/lib/python3.12/site-packages/google/cloud/storage/blob.py", line 2851, in upload_from_file
    self._prep_and_do_upload(
  File "/home/airflow/.local/lib/python3.12/site-packages/google/cloud/storage/blob.py", line 2718, in _prep_and_do_upload
    _raise_from_invalid_response(exc)
  File "/home/airflow/.local/lib/python3.12/site-packages/google/cloud/storage/blob.py", line 4908, in _raise_from_invalid_response
    raise exceptions.from_http_status(response.status_code, message, response=response)
google.api_core.exceptions.TooManyRequests: 429 POST https://storage.googleapis.com/upload/storage/v1/b/gooutside-raw/o?uploadType=multipart: {
  "error": {
    "code": 429,
    "message": "The object gooutside-raw/air/bamberg/2024-01-03T1500.json exceeded the rate limit for object mutation operations (create, update, and delete). Please reduce your request rate. See https://cloud.google.com/storage/docs/gcs429.",
    "errors": [
      {
        "message": "The object gooutside-raw/air/bamberg/2024-01-03T1500.json exceeded the rate limit for object mutation operations (create, update, and delete). Please reduce your request rate. See https://cloud.google.com/storage/docs/gcs429.",
        "domain": "usageLimits",
        "reason": "rateLimitExceeded"
      }
    ]
  }
}
: ('Request failed with status code', 429, 'Expected one of', <HTTPStatus.OK: 200>)
[2025-04-08T14:37:08.596+0000] {local_task_job_runner.py:266} INFO - Task exited with return code 1
[2025-04-08T14:37:08.624+0000] {taskinstance.py:3901} INFO - 0 downstream tasks scheduled from follow-on schedule check
[2025-04-08T14:37:08.637+0000] {local_task_job_runner.py:245} INFO - ::endgroup::
